Workbook

Sheet Tong quan
A1: BANG THEO DOI TIEN DO - LO TRINH 12 TUAN BLOCKCHAIN DEVELOPER INTERN (RUST / SOLANA)
A3: Ngay bat dau: | B3: 46191
A4: Ngay ket thuc du kien (84 ngay): | B4: =B3+83 -> 46274
A6: TIEN DO TONG QUAN - BLOCKCHAIN
A7: Tong so ngay hoc | B7: 84
A8: So ngay da hoan thanh | B8: =COUNTIF('Theo doi hang ngay'!H2:H85,"Hoan thanh") -> 2
A9: So ngay dang lam | B9: =COUNTIF('Theo doi hang ngay'!H2:H85,"Dang lam") -> 4
A10: % Hoan thanh tong the | B10: =COUNTIF('Theo doi hang ngay'!H2:H85,"Hoan thanh")/84 -> 0.023809524
A11: Tong so gio da hoc | B11: =SUM('Theo doi hang ngay'!I2:I85) -> 3.5
A13: TIEN DO THEO TUAN (Blockchain & DSA)
A14: Tuan | B14: Chu de Blockchain | C14: % Blockchain | D14: Chu de DSA | E14: % DSA
A15: 1 | B15: Blockchain Fundamentals | C15: =COUNTIFS('Theo doi hang ngay'!H2:H8,"Hoan thanh")/7 -> 0.28571429 | D15: Array & Hashing | E15: =COUNTIFS('Theo doi hang ngay'!N2:N8,"Hoan thanh")/7 -> 0.57142857
A16: 2 | B16: Cryptography chuyen sau | C16: =COUNTIFS('Theo doi hang ngay'!H9:H15,"Hoan thanh")/7 -> 0 | D16: Two Pointers & Sliding Window | E16: =COUNTIFS('Theo doi hang ngay'!N9:N15,"Hoan thanh")/7 -> 0
A17: 3 | B17: Bitcoin Architecture | C17: =COUNTIFS('Theo doi hang ngay'!H16:H22,"Hoan thanh")/7 -> 0 | D17: Stack | E17: =COUNTIFS('Theo doi hang ngay'!N16:N22,"Hoan thanh")/7 -> 0
A18: 4 | B18: Ethereum Architecture | C18: =COUNTIFS('Theo doi hang ngay'!H23:H29,"Hoan thanh")/7 -> 0 | D18: Binary Search | E18: =COUNTIFS('Theo doi hang ngay'!N23:N29,"Hoan thanh")/7 -> 0
A19: 5 | B19: Rust nang cao cho on-chain | C19: =COUNTIFS('Theo doi hang ngay'!H30:H36,"Hoan thanh")/7 -> 0 | D19: Linked List | E19: =COUNTIFS('Theo doi hang ngay'!N30:N36,"Hoan thanh")/7 -> 0
A20: 6 | B20: Solana Fundamentals (native) | C20: =COUNTIFS('Theo doi hang ngay'!H37:H43,"Hoan thanh")/7 -> 0 | D20: Trees nhap mon | E20: =COUNTIFS('Theo doi hang ngay'!N37:N43,"Hoan thanh")/7 -> 0
A21: 7 | B21: Anchor Framework | C21: =COUNTIFS('Theo doi hang ngay'!H44:H50,"Hoan thanh")/7 -> 0 | D21: Trees nang cao & Heap | E21: =COUNTIFS('Theo doi hang ngay'!N44:N50,"Hoan thanh")/7 -> 0
A22: 8 | B22: Smart Contract Dev - Escrow | C22: =COUNTIFS('Theo doi hang ngay'!H51:H57,"Hoan thanh")/7 -> 0 | D22: Backtracking | E22: =COUNTIFS('Theo doi hang ngay'!N51:N57,"Hoan thanh")/7 -> 0
A23: 9 | B23: SPL Token Program | C23: =COUNTIFS('Theo doi hang ngay'!H58:H64,"Hoan thanh")/7 -> 0 | D23: Graphs co ban | E23: =COUNTIFS('Theo doi hang ngay'!N58:N64,"Hoan thanh")/7 -> 0
A24: 10 | B24: NFT Program (Metaplex) | C24: =COUNTIFS('Theo doi hang ngay'!H65:H71,"Hoan thanh")/7 -> 0 | D24: Graphs nang cao | E24: =COUNTIFS('Theo doi hang ngay'!N65:N71,"Hoan thanh")/7 -> 0
A25: 11 | B25: DeFi co ban - Staking | C25: =COUNTIFS('Theo doi hang ngay'!H72:H78,"Hoan thanh")/7 -> 0 | D25: Dynamic Programming 1D | E25: =COUNTIFS('Theo doi hang ngay'!N72:N78,"Hoan thanh")/7 -> 0
A26: 12 | B26: Portfolio + Interview Prep | C26: =COUNTIFS('Theo doi hang ngay'!H79:H85,"Hoan thanh")/7 -> 0 | D26: DP 2D + Tong on | E26: =COUNTIFS('Theo doi hang ngay'!N79:N85,"Hoan thanh")/7 -> 0
A28: TONG QUAN TRACK DSA
A29: Tong so bai LeetCode | B29: 84
A30: So bai da hoan thanh | B30: =COUNTIF('Theo doi hang ngay'!N2:N85,"Hoan thanh") -> 4
A31: So bai dang lam | B31: =COUNTIF('Theo doi hang ngay'!N2:N85,"Dang lam") -> 2
A32: So bai da bo qua (Hard tuy chon) | B32: =COUNTIF('Theo doi hang ngay'!N2:N85,"Bo qua") -> 0
A33: % Hoan thanh DSA tong the | B33: =COUNTIF('Theo doi hang ngay'!N2:N85,"Hoan thanh")/84 -> 0.047619048
A35: PORTFOLIO PROJECTS
A36: Project | B36: Hoan thanh/Tong | C36: % Hoan thanh
A37: anchor-escrow | B37: ='Portfolio Projects'!G3 -> 0/7 | C37: ='Portfolio Projects'!H3 -> 0
A38: anchor-staking-pool | B38: ='Portfolio Projects'!G4 -> 0/7 | C38: ='Portfolio Projects'!H4 -> 0
A39: anchor-nft-minter | B39: ='Portfolio Projects'!G5 -> 0/6 | C39: ='Portfolio Projects'!H5 -> 0
A41: CAU HOI PHONG VAN
A42: Da tu tin tra loi | B42: ='Cau hoi phong van'!G2 -> 0/20

Sheet Theo doi hang ngay
A1: Tuan | B1: Ngay thu | C1: STT (1-84) | D1: Ngay hoc (date) | E1: Chu de chinh (Blockchain) | F1: Tai lieu chinh thuc | G1: Nhiem vu thuc hanh | H1: Trang thai (Blockchain) | I1: So gio hoc | J1: Ghi chu | K1: Chu de DSA tuan | L1: Bai LeetCode (Rust) | M1: Do kho DSA | N1: Trang thai DSA | O1: Ghi chu DSA
A2: 1 | B2: 1 | C2: 1 | D2: ='Tong quan'!$B$3+(C2-1) -> 46191 | E2: Decentralization, distributed ledger, block structure | F2: Bitcoin Whitepaper - bitcoin.org/bitcoin.pdf | G2: Viet tom tat 1 trang + ve so do block | H2: Hoan thanh | I2: 1.5 | J2: ghi nho ca keyword tieng anh | K2: Array & Hashing | L2: Two Sum | M2: Easy | N2: Hoan thanh | O2: chu y cac cu phap
A3: 1 | B3: 2 | C3: 2 | D3: ='Tong quan'!$B$3+(C3-1) -> 46192 | E3: Cryptographic hash function (SHA-256, Keccak256) | F3: RustCrypto/hashes - github.com/RustCrypto/hashes | G3: Code hash_block() bang crate sha2, test avalanche effect | H3: Hoan thanh | I3: 2 | J3: ghi nho ca keyword tieng anh | L3: Contains Duplicate | M3: Easy | N3: Hoan thanh | O3: su dung insert trong HashSet
A4: 1 | B4: 3 | C4: 3 | D4: ='Tong quan'!$B$3+(C4-1) -> 46193 | E4: Merkle Tree: cau truc, Merkle proof | F4: Bitcoin Developer Guide - Merkle Trees | G4: Code MerkleTree struct, build proof, verify_proof() | H4: Dang lam | L4: Valid Anagram | M4: Easy | N4: Hoan thanh | O4: su dung sort hay vi sort_unstable
A5: 1 | B5: 4 | C5: 4 | D5: ='Tong quan'!$B$3+(C5-1) -> 46194 | E5: Public-key cryptography, digital signature | F5: Cloudflare - ECC primer (blog.cloudflare.com) | G5: Dung ed25519-dalek: generate keypair, sign, verify | H5: Dang lam | L5: Group Anagrams | M5: Medium | N5: Hoan thanh | O5: nho entry, into_values
A6: 1 | B6: 5 | C6: 5 | D6: ='Tong quan'!$B$3+(C6-1) -> 46195 | E6: Consensus: PoW, PoS, BFT (gioi thieu Tower BFT) | F6: Ethereum.org - Consensus Mechanisms | G6: Code PoW miner tim nonce thoa target | H6: Dang lam | L6: Top K Frequent Elements | M6: Medium | N6: Dang lam
A7: 1 | B7: 6 | C7: 6 | D7: ='Tong quan'!$B$3+(C7-1) -> 46196 | E7: Project ngay: ghep thanh mini blockchain | F7: - | G7: Xay rust-mini-blockchain: block+hash+Merkle+PoW+sign | H7: Dang lam | L7: Product of Array Except Self | M7: Medium | N7: Dang lam
A8: 1 | B8: 7 | C8: 7 | D8: ='Tong quan'!$B$3+(C8-1) -> 46197 | E8: Checkpoint tuan 1 | F8: - | G8: Tu quiz + push rust-mini-blockchain len GitHub | H8: Chua bat dau | L8: Valid Sudoku | M8: Medium | N8: Chua bat dau
A9: 2 | B9: 1 | C9: 8 | D9: ='Tong quan'!$B$3+(C9-1) -> 46198 | E9: ECC truc giac, duong cong secp256k1 | F9: SEC2 spec - secg.org/sec2-v2.pdf | G9: Ve so do point addition tren duong cong | H9: Chua bat dau | K9: Two Pointers & Sliding Window | L9: Valid Palindrome | M9: Easy | N9: Chua bat dau
A10: 2 | B10: 2 | C10: 9 | D10: ='Tong quan'!$B$3+(C10-1) -> 46199 | E10: secp256k1 (BTC/ETH) vs ed25519 (Solana) | F10: Solana Docs - Keys & Wallets | G10: Tao keypair bang solana-keygen, verify | H10: Chua bat dau | L10: Two Sum II - Input Array Is Sorted | M10: Easy | N10: Chua bat dau
A11: 2 | B11: 3 | C11: 10 | D11: ='Tong quan'!$B$3+(C11-1) -> 46200 | E11: Address derivation (Bitcoin/Ethereum/Solana) | F11: Ethereum.org - Accounts | G11: Tu tinh address ETH tu public key bang Rust | H11: Chua bat dau | L11: 3Sum | M11: Medium | N11: Chua bat dau
A12: 2 | B12: 4 | C12: 11 | D12: ='Tong quan'!$B$3+(C12-1) -> 46201 | E12: BIP32/BIP39/BIP44 - mnemonic, HD wallet | F12: BIP-39 spec (github bitcoin/bips) | G12: Dung crate bip39 sinh mnemonic, derive Solana keypair | H12: Chua bat dau | L12: Container With Most Water | M12: Medium | N12: Chua bat dau
A13: 2 | B13: 5 | C13: 12 | D13: ='Tong quan'!$B$3+(C13-1) -> 46202 | E13: Transaction signing flow tong quat | F13: Solana Docs - Transactions | G13: Code Transaction struct + sign()/verify() doc lap | H13: Chua bat dau | L13: Best Time to Buy and Sell Stock | M13: Easy | N13: Chua bat dau
A14: 2 | B14: 6 | C14: 13 | D14: ='Tong quan'!$B$3+(C14-1) -> 46203 | E14: Project ngay: Wallet CLI tool | F14: - | G14: Xay rust-wallet-cli: gen keypair, sign, verify, address | H14: Chua bat dau | L14: Longest Substring Without Repeating Characters | M14: Medium | N14: Chua bat dau
A15: 2 | B15: 7 | C15: 14 | D15: ='Tong quan'!$B$3+(C15-1) -> 46204 | E15: Checkpoint tuan 2 | F15: - | G15: Quiz + push rust-wallet-cli len GitHub | H15: Chua bat dau | L15: Longest Repeating Character Replacement | M15: Medium | N15: Chua bat dau
A16: 3 | B16: 1 | C16: 15 | D16: ='Tong quan'!$B$3+(C16-1) -> 46205 | E16: UTXO model vs Account model | F16: Bitcoin Developer Guide - Transactions | G16: Ve so do UTXO input/output | H16: Chua bat dau | K16: Stack | L16: Valid Parentheses | M16: Easy | N16: Chua bat dau
A17: 3 | B17: 2 | C17: 16 | D17: ='Tong quan'!$B$3+(C17-1) -> 46206 | E17: Cau truc transaction Bitcoin (scriptSig/scriptPubKey) | F17: Bitcoin Developer Reference - Transactions | G17: Decode raw tx hex bang crate bitcoin (rust-bitcoin) | H17: Chua bat dau | L17: Min Stack | M17: Medium | N17: Chua bat dau
A18: 3 | B18: 3 | C18: 17 | D18: ='Tong quan'!$B$3+(C18-1) -> 46207 | E18: Block header, mining difficulty, Merkle root | F18: Bitcoin Developer Guide - Block Chain | G18: Lay block thuc qua Blockstream API, tu tinh lai Merkle root | H18: Chua bat dau | L18: Evaluate Reverse Polish Notation | M18: Medium | N18: Chua bat dau
A19: 3 | B19: 4 | C19: 18 | D19: ='Tong quan'!$B$3+(C19-1) -> 46208 | E19: Bitcoin Script co ban, multisig (P2SH) | F19: Bitcoin Script wiki (en.bitcoin.it/wiki/Script) | G19: Viet vi du OP_2 OP_3 OP_CHECKMULTISIG, giai thich flow | H19: Chua bat dau | L19: Generate Parentheses | M19: Medium | N19: Chua bat dau
A20: 3 | B20: 5 | C20: 19 | D20: ='Tong quan'!$B$3+(C20-1) -> 46209 | E20: Lightning Network tong quan | F20: Lightning Network whitepaper | G20: Tom tat 5 cau payment channel giai quyet van de gi | H20: Chua bat dau | L20: Daily Temperatures | M20: Medium | N20: Chua bat dau
A21: 3 | B21: 6 | C21: 20 | D21: ='Tong quan'!$B$3+(C21-1) -> 46210 | E21: Project ngay: Bitcoin tx parser | F21: - | G21: Xay bitcoin-tx-parser CLI in JSON inputs/outputs/fee | H21: Chua bat dau | L21: Car Fleet | M21: Medium | N21: Chua bat dau
A22: 3 | B22: 7 | C22: 21 | D22: ='Tong quan'!$B$3+(C22-1) -> 46211 | E22: Checkpoint tuan 3 | F22: - | G22: Quiz UTXO vs Account + push bitcoin-tx-parser | H22: Chua bat dau | L22: Largest Rectangle in Histogram | M22: Hard (tuy chon) | N22: Chua bat dau
A23: 4 | B23: 1 | C23: 22 | D23: ='Tong quan'!$B$3+(C23-1) -> 46212 | E23: Account model, World State (Merkle Patricia Trie) | F23: Ethereum.org - Accounts | G23: So sanh bang UTXO/Account/Solana (ban draft) | H23: Chua bat dau | K23: Binary Search | L23: Binary Search | M23: Easy | N23: Chua bat dau
A24: 4 | B24: 2 | C24: 23 | D24: ='Tong quan'!$B$3+(C24-1) -> 46213 | E24: EVM: bytecode, opcode, gas, execution model | F24: Ethereum.org - EVM | G24: Deploy contract counter qua Remix len Sepolia testnet | H24: Chua bat dau | L24: Search a 2D Matrix | M24: Medium | N24: Chua bat dau
A25: 4 | B25: 3 | C25: 24 | D25: ='Tong quan'!$B$3+(C25-1) -> 46214 | E25: ERC-20 / ERC-721 interface (doc hieu) | F25: EIP-20, EIP-721 (eips.ethereum.org) | G25: Doc interface, ghi chu so sanh voi SPL Token | H25: Chua bat dau | L25: Koko Eating Bananas | M25: Medium | N25: Chua bat dau
A26: 4 | B26: 4 | C26: 25 | D26: ='Tong quan'!$B$3+(C26-1) -> 46215 | E26: Gas mechanics, EIP-1559 (base fee + priority fee) | F26: Ethereum.org - Gas | G26: Tu tinh vi du phi gas thuc te | H26: Chua bat dau | L26: Find Minimum in Rotated Sorted Array | M26: Medium | N26: Chua bat dau
A27: 4 | B27: 5 | C27: 26 | D27: ='Tong quan'!$B$3+(C27-1) -> 46216 | E27: So sanh kien truc Bitcoin vs Ethereum vs Solana | F27: Solana Docs (solana.com/docs) | G27: Viet file comparison.md day du | H27: Chua bat dau | L27: Search in Rotated Sorted Array | M27: Medium | N27: Chua bat dau
A28: 4 | B28: 6 | C28: 27 | D28: ='Tong quan'!$B$3+(C28-1) -> 46217 | E28: Project ngay: Rust client query Ethereum testnet | F28: - | G28: Dung ethers-rs/alloy query balance + latest block Sepolia | H28: Chua bat dau | L28: Time Based Key-Value Store | M28: Medium | N28: Chua bat dau
A29: 4 | B29: 7 | C29: 28 | D29: ='Tong quan'!$B$3+(C29-1) -> 46218 | E29: Checkpoint tuan 4 | F29: - | G29: Quiz so sanh kien truc + hoan thien comparison.md | H29: Chua bat dau | L29: Median of Two Sorted Arrays | M29: Hard (tuy chon) | N29: Chua bat dau
A30: 5 | B30: 1 | C30: 29 | D30: ='Tong quan'!$B$3+(C30-1) -> 46219 | E30: Borsh serialization - vi sao Solana dung Borsh | F30: Borsh specification - borsh.io | G30: Derive BorshSerialize/Deserialize, in ra bytes | H30: Chua bat dau | K30: Linked List | L30: Reverse Linked List | M30: Easy | N30: Chua bat dau
A31: 5 | B31: 2 | C31: 30 | D31: ='Tong quan'!$B$3+(C31-1) -> 46220 | E31: Generic vs dyn Trait (anh huong compute unit) | F31: Rust Book Ch.10 & Ch.17 (doc.rust-lang.org/book) | G31: So sanh binary size bang cargo bloat | H31: Chua bat dau | L31: Merge Two Sorted Lists | M31: Easy | N31: Chua bat dau
A32: 5 | B32: 3 | C32: 31 | D32: ='Tong quan'!$B$3+(C32-1) -> 46221 | E32: Memory layout: #[repr(C)], alignment/padding | F32: Rust Reference - Type Layout | G32: Kiem tra size_of/align_of truoc/sau khi them repr(C) | H32: Chua bat dau | L32: Reorder List | M32: Medium | N32: Chua bat dau
A33: 5 | B33: 4 | C33: 32 | D33: ='Tong quan'!$B$3+(C33-1) -> 46222 | E33: Macro co ban: macro_rules! | F33: Rust Book Ch.19.5 - Macros | G33: Viet macro tu sinh ham getter/setter cho struct | H33: Chua bat dau | L33: Remove Nth Node From End of List | M33: Medium | N33: Chua bat dau
A34: 5 | B34: 5 | C34: 33 | D34: ='Tong quan'!$B$3+(C34-1) -> 46223 | E34: Error handling: thiserror vs ProgramError | F34: thiserror docs (docs.rs/thiserror) | G34: Refactor code Axum cu dung thiserror | H34: Chua bat dau | L34: Add Two Numbers | M34: Medium | N34: Chua bat dau
A35: 5 | B35: 6 | C35: 34 | D35: ='Tong quan'!$B$3+(C35-1) -> 46224 | E35: Project ngay: Borsh playground + benchmark | F35: - | G35: Repo borsh-playground: unit test + benchmark criterion | H35: Chua bat dau | L35: Copy List with Random Pointer | M35: Medium | N35: Chua bat dau
A36: 5 | B36: 7 | C36: 35 | D36: ='Tong quan'!$B$3+(C36-1) -> 46225 | E36: Checkpoint tuan 5 | F36: - | G36: Quiz vi sao tranh Box/Rc on-chain + push borsh-playground | H36: Chua bat dau | L36: Linked List Cycle | M36: Easy | N36: Chua bat dau
A37: 6 | B37: 1 | C37: 36 | D37: ='Tong quan'!$B$3+(C37-1) -> 46226 | E37: Solana account model: executable vs data, rent | F37: Solana Docs - Accounts | G37: Xem 1 account thuc qua CLI 'solana account <address>' | H37: Chua bat dau | K37: Trees nhap mon | L37: Invert Binary Tree | M37: Easy | N37: Chua bat dau
A38: 6 | B38: 2 | C38: 37 | D38: ='Tong quan'!$B$3+(C38-1) -> 46227 | E38: Transaction & Instruction structure | F38: Solana Docs - Transactions | G38: Ve so do 1 transaction nhieu instruction | H38: Chua bat dau | L38: Maximum Depth of Binary Tree | M38: Easy | N38: Chua bat dau
A39: 6 | B39: 3 | C39: 38 | D39: ='Tong quan'!$B$3+(C39-1) -> 46228 | E39: Program Derived Address (PDA): derive, bump seed | F39: Solana Docs - PDA | G39: Code find_program_address voi nhieu seed khac nhau | H39: Chua bat dau | L39: Same Tree | M39: Easy | N39: Chua bat dau
A40: 6 | B40: 4 | C40: 39 | D40: ='Tong quan'!$B$3+(C40-1) -> 46229 | E40: Cross-Program Invocation (CPI) - tong quan | F40: Solana Docs - CPI | G40: Doc source SPL Token program phan invoke() | H40: Chua bat dau | L40: Subtree of Another Tree | M40: Easy | N40: Chua bat dau
...

Sheet Checkpoint theo tuan
A1: Tuan | B1: Chu de chinh (Blockchain) | C1: Tieu chi checkpoint | D1: Da hoan thanh ngay 7? | E1: Dat / Chua dat | F1: Chu de DSA tuan nay | G1: % DSA hoan thanh tuan | H1: Ghi chu
A2: 1 | B2: Blockchain Fundamentals | C2: Giai thich duoc hash/Merkle/PoW, code rust-mini-blockchain chay duoc | D2: ='Theo doi hang ngay'!H8 -> Chua bat dau | E2: =IF(D2="Hoan thanh","Dat","Chua dat") -> Chua dat | F2: Array & Hashing | G2: =COUNTIFS('Theo doi hang ngay'!N2:N8,"Hoan thanh")/7 -> 0.57142857
A3: 2 | B3: Cryptography chuyen sau | C3: Tu tao keypair, sign/verify thanh thao, rust-wallet-cli hoan chinh | D3: ='Theo doi hang ngay'!H15 -> Chua bat dau | E3: =IF(D3="Hoan thanh","Dat","Chua dat") -> Chua dat | F3: Two Pointers & Sliding Window | G3: =COUNTIFS('Theo doi hang ngay'!N9:N15,"Hoan thanh")/7 -> 0
A4: 3 | B4: Bitcoin Architecture | C4: Hieu UTXO, parse duoc raw Bitcoin transaction | D4: ='Theo doi hang ngay'!H22 -> Chua bat dau | E4: =IF(D4="Hoan thanh","Dat","Chua dat") -> Chua dat | F4: Stack | G4: =COUNTIFS('Theo doi hang ngay'!N16:N22,"Hoan thanh")/7 -> 0
A5: 4 | B5: Ethereum Architecture | C5: Hieu EVM/gas, viet xong file so sanh BTC/ETH/Solana | D5: ='Theo doi hang ngay'!H29 -> Chua bat dau | E5: =IF(D5="Hoan thanh","Dat","Chua dat") -> Chua dat | F5: Binary Search | G5: =COUNTIFS('Theo doi hang ngay'!N23:N29,"Hoan thanh")/7 -> 0
A6: 5 | B6: Rust nang cao cho on-chain | C6: Thanh thao Borsh, hieu memory layout, benchmark xong | D6: ='Theo doi hang ngay'!H36 -> Chua bat dau | E6: =IF(D6="Hoan thanh","Dat","Chua dat") -> Chua dat | F6: Linked List | G6: =COUNTIFS('Theo doi hang ngay'!N30:N36,"Hoan thanh")/7 -> 0
A7: 6 | B7: Solana Fundamentals (native) | C7: Tu viet duoc native Solana program, hieu PDA/CPI co ban | D7: ='Theo doi hang ngay'!H43 -> Chua bat dau | E7: =IF(D7="Hoan thanh","Dat","Chua dat") -> Chua dat | F7: Trees nhap mon | G7: =COUNTIFS('Theo doi hang ngay'!N37:N43,"Hoan thanh")/7 -> 0
A8: 7 | B8: Anchor Framework | C8: Tu viet Anchor program tu dau khong copy template | D8: ='Theo doi hang ngay'!H50 -> Chua bat dau | E8: =IF(D8="Hoan thanh","Dat","Chua dat") -> Chua dat | F8: Trees nang cao & Heap | G8: =COUNTIFS('Theo doi hang ngay'!N44:N50,"Hoan thanh")/7 -> 0
A9: 8 | B9: Smart Contract Dev - Escrow | C9: anchor-escrow deploy devnet thanh cong, qua security review | D9: ='Theo doi hang ngay'!H57 -> Chua bat dau | E9: =IF(D9="Hoan thanh","Dat","Chua dat") -> Chua dat | F9: Backtracking | G9: =COUNTIFS('Theo doi hang ngay'!N51:N57,"Hoan thanh")/7 -> 0
A10: 9 | B10: SPL Token Program | C10: spl-token-faucet hoat dong dung, hieu ro ATA | D10: ='Theo doi hang ngay'!H64 -> Chua bat dau | E10: =IF(D10="Hoan thanh","Dat","Chua dat") -> Chua dat | F10: Graphs co ban | G10: =COUNTIFS('Theo doi hang ngay'!N58:N64,"Hoan thanh")/7 -> 0
A11: 10 | B11: NFT Program (Metaplex) | C11: anchor-nft-minter mint thanh cong, metadata hien dung tren Explorer | D11: ='Theo doi hang ngay'!H71 -> Chua bat dau | E11: =IF(D11="Hoan thanh","Dat","Chua dat") -> Chua dat | F11: Graphs nang cao | G11: =COUNTIFS('Theo doi hang ngay'!N65:N71,"Hoan thanh")/7 -> 0
A12: 11 | B12: DeFi co ban - Staking | C12: anchor-staking-pool tinh reward dung, khong overflow | D12: ='Theo doi hang ngay'!H78 -> Chua bat dau | E12: =IF(D12="Hoan thanh","Dat","Chua dat") -> Chua dat | F12: Dynamic Programming 1D | G12: =COUNTIFS('Theo doi hang ngay'!N72:N78,"Hoan thanh")/7 -> 0
A13: 12 | B13: Portfolio + Interview Prep | C13: 3 portfolio hoan chinh, tra loi tron 20 cau hoi phong van | D13: ='Theo doi hang ngay'!H85 -> Chua bat dau | E13: =IF(D13="Hoan thanh","Dat","Chua dat") -> Chua dat | F13: DP 2D + Tong on | G13: =COUNTIFS('Theo doi hang ngay'!N79:N85,"Hoan thanh")/7 -> 0

Sheet Portfolio Projects
A1: Project | B1: Milestone | C1: Trang thai | D1: Ghi chu | F1: TONG HOP TIEN DO PROJECT
A2: anchor-escrow | B2: Thiet ke account/state (EscrowState, Vault) | C2: Chua bat dau | F2: Project | G2: Hoan thanh / Tong | H2: % Hoan thanh
A3: anchor-escrow | B3: Implement initialize_escrow + CPI transfer vao vault | C3: Chua bat dau | F3: anchor-escrow | G3: =COUNTIFS($A$2:$A$21,F3,$C$2:$C$21,"Hoan thanh")&"/"&COUNTIF($A$2:$A$21,F3) -> 0/7 | H3: =COUNTIFS($A$2:$A$21,F3,$C$2:$C$21,"Hoan thanh")/COUNTIF($A$2:$A$21,F3) -> 0
A4: anchor-escrow | B4: Implement exchange | C4: Chua bat dau | F4: anchor-staking-pool | G4: =COUNTIFS($A$2:$A$21,F4,$C$2:$C$21,"Hoan thanh")&"/"&COUNTIF($A$2:$A$21,F4) -> 0/7 | H4: =COUNTIFS($A$2:$A$21,F4,$C$2:$C$21,"Hoan thanh")/COUNTIF($A$2:$A$21,F4) -> 0
A5: anchor-escrow | B5: Implement cancel | C5: Chua bat dau | F5: anchor-nft-minter | G5: =COUNTIFS($A$2:$A$21,F5,$C$2:$C$21,"Hoan thanh")&"/"&COUNTIF($A$2:$A$21,F5) -> 0/6 | H5: =COUNTIFS($A$2:$A$21,F5,$C$2:$C$21,"Hoan thanh")/COUNTIF($A$2:$A$21,F5) -> 0
A6: anchor-escrow | B6: Viet test day du (happy path + fail cases) | C6: Chua bat dau
A7: anchor-escrow | B7: Security review theo checklist sealevel-attacks | C7: Chua bat dau
A8: anchor-escrow | B8: Deploy devnet + README hoan chinh | C8: Chua bat dau
A9: anchor-staking-pool | B9: Thiet ke StakePool / UserStake (PDA) | C9: Chua bat dau
A10: anchor-staking-pool | B10: Implement initialize_pool | C10: Chua bat dau
A11: anchor-staking-pool | B11: Implement stake + update_rewards (checked_*) | C11: Chua bat dau
A12: anchor-staking-pool | B12: Implement claim_rewards | C12: Chua bat dau
A13: anchor-staking-pool | B13: Implement unstake | C13: Chua bat dau
A14: anchor-staking-pool | B14: Test day du (stake/claim/unstake) | C14: Chua bat dau
A15: anchor-staking-pool | B15: Deploy devnet + README hoan chinh | C15: Chua bat dau
A16: anchor-nft-minter | B16: Doc & hieu Metaplex Token Metadata | C16: Chua bat dau
A17: anchor-nft-minter | B17: Implement mint_nft (tao mint + CPI metadata) | C17: Chua bat dau
... A21: anchor-nft-minter | B21: Deploy devnet + README hoan chinh | C21: Chua bat dau

Sheet Cau hoi phong van
A1: STT | B1: Nhom | C1: Cau hoi | D1: Da tu tin tra loi? | E1: Ghi chu / Diem can cai thien | G1: So cau da tu tin
A2: 1 | B2: Fundamentals | C2: Blockchain la gi, khac gi database phan tan thong thuong? | D2: Chua | G2: =COUNTIF(D2:D21,"Co")&"/"&20 -> 0/20
A3: 2 | B3: Fundamentals | C3: Hash function co tinh chat gi? Vi sao quan trong voi blockchain? | D3: Chua
A4: 3 | B4: Fundamentals | C4: Digital signature hoat dong nhu the nao? Phan biet voi ma hoa (encryption)? | D4: Chua
A5: 4 | B5: Fundamentals | C5: Merkle Tree dung de lam gi trong blockchain? | D5: Chua
A6: 5 | B6: Bitcoin/Ethereum | C6: UTXO model khac Account model nhu the nao? Uu nhuoc diem moi loai? | D6: Chua
A7: 6 | B7: Bitcoin/Ethereum | C7: EVM la gi? Gas dung de lam gi? | D7: Chua
A8: 7 | B8: Bitcoin/Ethereum | C8: ERC-20 va ERC-721 khac nhau o diem gi? | D8: Chua
A9: 8 | B9: Solana core | C9: Vi sao Solana dat throughput cao hon Ethereum L1? | D9: Chua
A10: 9 | B10: Solana core | C10: Account model cua Solana hoat dong ra sao? Khac Ethereum the nao? | D10: Chua
A11: 10 | B11: Solana core | C11: PDA (Program Derived Address) la gi, dung de lam gi? | D11: Chua
A12: 11 | B12: Solana core | C12: Rent tren Solana la gi? | D12: Chua
A13: 12 | B13: Solana core | C13: CPI (Cross-Program Invocation) la gi? Cho vi du thuc te. | D13: Chua
A14: 13 | B14: Solana core | C14: Compute budget / compute unit la gi? Tai sao phai quan tam? | D14: Chua
... A21: 20 | B21: Token/NFT/DeFi | C21: AMM hoat dong theo cong thuc nao? Impermanent loss la gi? | D21: Chua
